Workbook

Sheet 증강_300
A1: 순번 | B1: 질문 ID | C1: 질문 | D1: Tool 선택 결과 | E1: 판정 | F1: 정답 Tool | G1: 비고 | H1: Semantic Type | I1: 난이도 | J1: Factors | K1: 실행 방식 | L1: 수정 이력 | M1: canonical_id | N1: family_id | O1: risk_tags | P1: vendor100 최근접 ID | Q1: vendor100 Jaccard | R1: vendor100 동일 정답 | S1: vendor100 template 겹침 | T1: 기타 보호셋 최근접 | U1: 기타 보호셋 Jaccard | V1: 사용 상태(제안) | W1: 상태 사유
A2: 101 | B2: 101 | C2: 대구 중구의 택시 통행량은? | F2: get_place_scope(name=중구, region=대구) get_passage_count(scope=$resolve.scope) | G2: DATA_AUGMENTATION_GUIDE 기준 의미·조건 조합 증강 | H2: PASSAGE_COUNT | I2: simple | J2: spatial_ref=대구/중구; space=admin | K2: admin | M2: aug300-101 | N2: F064 | O2: agg_absent | P2: 018 | Q2: 0.429 | S2: Y | T2: selection_v2 old44/g37 | U2: 0.467 | V2: train | W2: family 단위 분할(train family)
A3: 102 | B3: 102 | C3: 동대구역에서 택시가 얼마나 통행했어? | F3: get_place_scope(name=동대구역) get_passage_count(scope=$resolve.scope) | G3: DATA_AUGMENTATION_GUIDE 기준 의미·조건 조합 증강 | H3: PASSAGE_COUNT | I3: simple | J3: spatial_ref=동대구역; space=place | K3: place | M3: aug300-102 | N3: F051 | O3: agg_absent | P3: 018 | Q3: 0.087 | S3: N | T3: valid98 heldout_v9/h01 | U3: 0.24 | V3: train | W3: family 단위 분할(train family)
A4: 103 | B4: 103 | C4: scope:h3:8830e1d85ffffff 기준 택시 통행 건수를 알려줘. | F4: get_passage_count(scope=scope:h3:8830e1d85ffffff) | G4: DATA_AUGMENTATION_GUIDE 기준 의미·조건 조합 증강 | H4: PASSAGE_COUNT | I4: simple | J4: spatial_ref=scope:h3:8830e1d85ffffff; space=direct_scope | K4: direct_scope | M4: aug300-103 | N4: F043 | O4: agg_absent, direct_scope | P4: 082 | Q4: 0.391 | S4: N | T4: selection_v2 indepv3/m28 | U4: 0.302 | V4: holdout | W4: family 단위 분할(holdout family)
A5: 104 | B5: 104 | C5: 부산 광안리 주변의 택시 통행량을 알려줘. | F5: get_place_scope(name=광안리, region=부산, include_vicinity=true) get_passage_count(scope=$resolve.scope) | G5: DATA_AUGMENTATION_GUIDE 기준 의미·조건 조합 증강 | H5: PASSAGE_COUNT | I5: simple | J5: spatial_ref=부산/광안리(vicinity); space=vicinity | K5: vicinity | M5: aug300-104 | N5: F047 | O5: vicinity, agg_absent | P5: 034 | Q5: 0.286 | S5: N | T5: valid98 heldout_v9/h26 | U5: 0.25 | V5: train | W5: family 단위 분할(train family)
A6: 105 | B6: 105 | C6: 대구 신천동의 공차 택시 통행량은? | F6: get_place_scope(name=신천동, region=대구) get_passage_count(scope=$resolve.scope, taxi_status=vacant) | G6: DATA_AUGMENTATION_GUIDE 기준 의미·조건 조합 증강 | H6: PASSAGE_COUNT | I6: simple | J6: spatial_ref=대구/신천동; space=admin; taxi_status=vacant | K6: admin | M6: aug300-105 | N6: F062 | O6: status_vacant, agg_absent | P6: 019 | Q6: 0.812 | S6: Y | T6: selection_v2 old44/g37 | U6: 0.25 | V6: 보류_vendor100 | W6: vendor100 019와 Jaccard 0.812. 결정 D1에 따라 train 복귀 가능(holdout에는 넣지 않음)
A7: 106 | B7: 106 | C7: 부산 광안동에서 법인택시가 얼마나 통행했어? | F7: get_place_scope(name=광안동, region=부산) get_passage_count(scope=$resolve.scope, taxi_type=corporate) | G7: DATA_AUGMENTATION_GUIDE 기준 의미·조건 조합 증강 | H7: PASSAGE_COUNT | I7: simple | J7: spatial_ref=부산/광안동; space=admin; taxi_type=corporate | K7: admin | M7: aug300-106 | N7: F063 | O7: agg_absent | P7: 023 | Q7: 0.125 | S7: N | T7: selection_v2 indepv2/n08 | U7: 0.119 | V7: train | W7: family 단위 분할(train family)
A8: 107 | B8: 107 | C8: 대구 두산동 기준 개인택시 통행 건수를 알려줘. | F8: get_place_scope(name=두산동, region=대구) get_passage_count(scope=$resolve.scope, taxi_type=private) | G8: DATA_AUGMENTATION_GUIDE 기준 의미·조건 조합 증강 | H8: PASSAGE_COUNT | I8: simple | J8: spatial_ref=대구/두산동; space=admin; taxi_type=private | K8: admin | M8: aug300-107 | N8: F063 | O8: agg_absent | P8: 060 | Q8: 0.111 | S8: N | T8: valid98 heldout_v9/h26 | U8: 0.105 | V8: train | W8: family 단위 분할(train family)
A9: 108 | B9: 108 | C9: 이번 달 scope:district:2600000000의 택시 통행량을 알려줘. | F9: get_passage_count(scope=scope:district:2600000000, date=this_month) | G9: DATA_AUGMENTATION_GUIDE 기준 의미·조건 조합 증강 | H9: PASSAGE_COUNT | I9: simple | J9: spatial_ref=scope:district:2600000000; space=direct_scope; date=this_month | K9: direct_scope | M9: aug300-108 | N9: F041 | O9: agg_absent, direct_scope | P9: 088 | Q9: 0.625 | S9: N | T9: valid98 heldout_v9/h36 | U9: 0.396 | V9: 보류_vendor100 | W9: vendor100 088와 Jaccard 0.625. 결정 D1에 따라 train 복귀 가능(holdout에는 넣지 않음)
A10: 109 | B10: 109 | C10: 이번 주 대구 동성로의 택시 통행량은? | F10: get_place_scope(name=동성로, region=대구) get_passage_count(scope=$resolve.scope, date=this_week) | G10: DATA_AUGMENTATION_GUIDE 기준 의미·조건 조합 증강 | H10: PASSAGE_COUNT | I10: simple | J10: spatial_ref=대구/동성로; space=place; date=this_week | K10: place | M10: aug300-109 | N10: F060 | O10: agg_absent | P10: 018 | Q10: 0.333 | S10: N | T10: selection_v2 old44/g37 | U10: 0.3 | V10: train | W10: family 단위 분할(train family)
A11: 110 | B11: 110 | C11: 부산 초읍동 어린이대공원 주변에서 실차 택시가 얼마나 통행했어? | F11: get_place_scope(name=어린이대공원, region=부산 초읍동, include_vicinity=true) get_passage_count(scope=$resolve.scope, taxi_status=occupied) | G11: DATA_AUGMENTATION_GUIDE 기준 의미·조건 조합 증강 | H11: PASSAGE_COUNT | I11: simple | J11: spatial_ref=부산 초읍동/어린이대공원(vicinity); space=vicinity; taxi_status=occupied | K11: vicinity | M11: aug300-110 | N11: F046 | O11: occupied_passage, vicinity, agg_absent | P11: 074 | Q11: 0.361 | S11: N | T11: selection_v2 indepv2/n33 | U11: 0.104 | V11: train | W11: family 단위 분할(train family)
A12: 111 | B12: 111 | C12: 대구 달서구의 읍면동별 택시 통행량을 알려줘. | F12: get_place_scope(name=달서구, region=대구) get_passage_count(scope=$resolve.scope, dimension=emd) | G12: DATA_AUGMENTATION_GUIDE 기준 의미·조건 조합 증강 | H12: PASSAGE_COUNT | I12: simple | J12: spatial_ref=대구/달서구; space=admin; group_by=emd | K12: admin | M12: aug300-111 | N12: F061 | O12: agg_absent, group_by | P12: 060 | Q12: 0.379 | S12: N | T12: valid98 heldout_v9/h26 | U12: 0.235 | V12: train | W12: family 단위 분할(train family)
A13: 112 | B13: 112 | C13: scope:district:2700000000의 시군구별 택시 통행량을 알려줘. | F13: get_passage_count(scope=scope:district:2700000000, dimension=sigungu) | G13: DATA_AUGMENTATION_GUIDE 기준 의미·조건 조합 증강 | H13: PASSAGE_COUNT | I13: simple | J13: spatial_ref=scope:district:2700000000; space=direct_scope; group_by=sigungu | K13: direct_scope | M13: aug300-112 | N13: F042 | O13: agg_absent, group_by, direct_scope | P13: 042 | Q13: 0.524 | S13: N | T13: valid98 heldout_v9/h36 | U13: 0.36 | V13: 보류_vendor100 | W13: vendor100 042와 Jaccard 0.524. 결정 D1에 따라 train 복귀 가능(holdout에는 넣지 않음)
... A15: 114 | B15: 114 | C15: 주말 대구 두류동의 개인 대기영업 택시 통행량은? | F15: get_place_scope(name=두류동, region=대구) get_passage_count(scope=$resolve.scope, date=weekend, taxi_type=private, taxi_status=stationary) | G15: DATA_AUGMENTATION_GUIDE 기준 의미·조건 조합 증강 | H15: PASSAGE_COUNT | I15: medium | J15: spatial_ref=대구/두류동; space=admin; date=weekend; taxi_type=private; taxi_status=stationary | K15: admin | M15: aug300-114 | N15: F058 | O15: status_stationary, agg_absent | P15: 055 | Q15: 0.81 | S15: Y | T15: selection_v2 old44/g03 | U15: 0.226 | V15: 보류_vendor100 | W15: vendor100 055와 Jaccard 0.810. 결정 D1에 따라 train 복귀 가능(holdout에는 넣지 않음)
A16: 115 | B16: 115 | C16: 주중 오전 8시 30분부터 10시까지 부산 초읍동에서 개인 공차 택시가 얼마나 통행했어? | F16: get_place_scope(name=초읍동, region=부산) get_passage_count(scope=$resolve.scope, date=weekday, time=083000-100000, taxi_type=private, taxi_status=vacant) | G16: DATA_AUGMENTATION_GUIDE 기준 의미·조건 조합 증강 | H16: PASSAGE_COUNT | I16: medium | J16: spatial_ref=부산/초읍동; space=admin; date=weekday; time=083000-100000; taxi_type=private; taxi_status=vacant | K16: admin | M16: aug300-115 | N16: F057 | O16: status_vacant, agg_absent | P16: 072 | Q16: 0.396 | R16: 072 | S16: Y | T16: selection_v2 old44/g39 | U16: 0.173 | V16: 보류_vendor100 | W16: 정답 tool call이 vendor100 072와 같음. 결정 D1에 따라 train 복귀 가능(holdout에는 넣지 않음)
A17: 116 | B17: 116 | C17: 지난달 부산 광안리 기준 법인 실차 택시 통행 건수를 알려줘. | F17: get_place_scope(name=광안리, region=부산) get_passage_count(scope=$resolve.scope, date=last_month, taxi_type=corporate, taxi_status=occupied) | G17: DATA_AUGMENTATION_GUIDE 기준 의미·조건 조합 증강 | H17: PASSAGE_COUNT | I17: medium | J17: spatial_ref=부산/광안리; space=place; date=last_month; taxi_type=corporate; taxi_status=occupied | K17: place | M17: aug300-116 | N17: F047 | O17: occupied_passage, agg_absent | P17: 054 | Q17: 0.2 | S17: Y | T17: valid98 heldout_v9/h05 | U17: 0.102 | V17: train | W17: family 단위 분할(train family)
A18: 117 | B18: 117 | C18: 지난주 오후 6시부터 8시까지 scope:district:2726000000의 공차 택시 통행량을 알려줘. | F18: get_passage_count(scope=scope:district:2726000000, date=last_week, time=180000-200000, taxi_status=vacant) | G18: DATA_AUGMENTATION_GUIDE 기준 의미·조건 조합 증강 | H18: PASSAGE_COUNT | I18: medium | J18: spatial_ref=scope:district:2726000000; space=direct_scope; date=last_week; time=180000-200000; taxi_status=vacant | K18: direct_scope | M18: aug300-117 | N18: F039 | O18: status_vacant, agg_absent, direct_scope | P18: 042 | Q18: 0.481 | S18: N | T18: valid98 heldout_v9/h36 | U18: 0.373 | V18: train | W18: family 단위 분할(train family)
A19: 118 | B19: 118 | C19: 휴일 오후 6시부터 8시까지 동대구역 주변의 법인택시 통행량은? | F19: get_place_scope(name=동대구역, include_vicinity=true) get_passage_count(scope=$resolve.scope, date=holiday, time=180000-200000, taxi_type=corporate) | G19: DATA_AUGMENTATION_GUIDE 기준 의미·조건 조합 증강 | H19: PASSAGE_COUNT | I19: medium | J19: spatial_ref=동대구역(vicinity); space=vicinity; date=holiday; time=180000-200000; taxi_type=corporate | K19: vicinity | M19: aug300-118 | N19: F051 | O19: vicinity, agg_absent | P19: 001 | Q19: 0.432 | S19: N | T19: aux_test_v1 final_v12/f31 | U19: 0.217 | V19: train | W19: family 단위 분할(train family)
A20: 119 | B20: 119 | C20: 이번 주 대구 중심지 주변에서 실차 택시가 얼마나 통행했어? | F20: get_place_scope(name=중심지, region=대구, include_vicinity=true) get_passage_count(scope=$resolve.scope, date=this_week, taxi_status=occupied) | G20: DATA_AUGMENTATION_GUIDE 기준 의미·조건 조합 증강 | H20: PASSAGE_COUNT | I20: medium | J20: spatial_ref=대구/중심지(vicinity); space=vicinity; date=this_week; taxi_status=occupied | K20: vicinity | M20: aug300-119 | N20: F045 | O20: occupied_passage, vicinity, agg_absent | P20: 058 | Q20: 0.086 | S20: Y | T20: selection_v2 contrast/c03d | U20: 0.079 | V20: train | W20: family 단위 분할(train family)
A21: 120 | B21: 120 | C21: 지난주 대구 중구의 읍면동별 공차 택시 통행량을 알려줘. | F21: get_place_scope(name=중구, region=대구) get_passage_count(scope=$resolve.scope, date=last_week, taxi_status=vacant, dimension=emd) | G21: DATA_AUGMENTATION_GUIDE 기준 의미·조건 조합 증강 | H21: PASSAGE_COUNT | I21: medium | J21: spatial_ref=대구/중구; space=admin; date=last_week; taxi_status=vacant; group_by=emd | K21: admin | M21: aug300-120 | N21: F055 | O21: status_vacant, agg_absent, group_by | P21: 080 | Q21: 0.483 | S21: N | T21: selection_v2 old44/g06 | U21: 0.406 | V21: train | W21: family 단위 분할(train family)
A22: 121 | B22: 121 | C22: 이번 주 부산의 시군구별 법인택시 통행량을 알려줘. | F22: get_place_scope(name=부산) get_passage_count(scope=$resolve.scope, date=this_week, taxi_type=corporate, dimension=sigungu) | G22: DATA_AUGMENTATION_GUIDE 기준 의미·조건 조합 증강 | H22: PASSAGE_COUNT | I22: medium | J22: spatial_ref=부산; space=admin; date=this_week; taxi_type=corporate; group_by=sigungu | K22: admin | M22: aug300-121 | N22: F050 | O22: agg_absent, group_by | P22: 002 | Q22: 0.452 | S22: N | T22: valid98 heldout_v9/h26 | U22: 0.222 | V22: holdout | W22: family 단위 분할(holdout family)
A23: 122 | B23: 122 | C23: 주말 대구 달서구의 읍면동별 개인택시 통행량을 알려줘. | F23: get_place_scope(name=달서구, region=대구) get_passage_count(scope=$resolve.scope, date=weekend, taxi_type=private, dimension=emd) | G23: DATA_AUGMENTATION_GUIDE 기준 의미·조건 조합 증강 | H23: PASSAGE_COUNT | I23: medium | J23: spatial_ref=대구/달서구; space=admin; date=weekend; taxi_type=private; group_by=emd | K23: admin | M23: aug300-122 | N23: F056 | O23: agg_absent, group_by | P23: 060 | Q23: 0.257 | S23: N | T23: selection_v2 old44/g03 | U23: 0.242 | V23: train | W23: family 단위 분할(train family)
A24: 123 | B24: 123 | C24: 이번 달 scope:district:2600000000의 읍면동별 실차 택시 통행량을 알려줘. | F24: get_passage_count(scope=scope:district:2600000000, date=this_month, taxi_status=occupied, dimension=emd) | G24: DATA_AUGMENTATION_GUIDE 기준 의미·조건 조합 증강 | H24: PASSAGE_COUNT | I24: medium | J24: spatial_ref=scope:district:2600000000; space=direct_scope; date=this_month; taxi_status=occupied; group_by=emd | K24: direct_scope | M24: aug300-123 | N24: F038 | O24: occupied_passage, agg_absent, group_by, direct_scope | P24: 088 | Q24: 0.614 | S24: N | T24: valid98 heldout_v9/h36 | U24: 0.352 | V24: 보류_vendor100 | W24: vendor100 088와 Jaccard 0.614. 결정 D1에 따라 train 복귀 가능(holdout에는 넣지 않음)
A25: 124 | B25: 124 | C25: 지난달 대구 수성구의 H3 셀별 법인택시 통행량을 알려줘. | F25: get_place_scope(name=수성구, region=대구) get_passage_count(scope=$resolve.scope, date=last_month, taxi_type=corporate, dimension=h3) | G25: DATA_AUGMENTATION_GUIDE 기준 의미·조건 조합 증강 | H25: PASSAGE_COUNT | I25: medium | J25: spatial_ref=대구/수성구; space=admin; date=last_month; taxi_type=corporate; group_by=h3 | K25: admin | M25: aug300-124 | N25: F056 | O25: agg_absent, group_by | P25: 037 | Q25: 0.256 | S25: N | T25: valid98 heldout_v9/h26 | U25: 0.205 | V25: train | W25: family 단위 분할(train family)
A26: 125 | B26: 125 | C26: 2026년 6월 2일 오후 6시부터 8시까지 부산 광안동의 실차 택시 통행량을 알려줘. | F26: get_place_scope(name=광안동, region=부산) get_passage_count(scope=$resolve.scope, date=20260602, time=180000-200000, taxi_status=occupied) | G26: DATA_AUGMENTATION_GUIDE 기준 의미·조건 조합 증강 | H26: PASSAGE_COUNT | I26: medium | J26: spatial_ref=부산/광안동; space=admin; date=20260602; time=180000-200000; taxi_status=occupied | K26: admin | M26: aug300-125 | N26: F059 | O26: occupied_passage, agg_absent | P26: 054 | Q26: 0.297 | S26: N | T26: selection_v2 old44/g18 | U26: 0.2 | V26: train | W26: family 단위 분할(train family)
A27: 126 | B27: 126 | C27: 지난주 오전 7시부터 9시까지 대구 동인동의 공차 택시 통행량은? | F27: get_place_scope(name=동인동, region=대구) get_passage_count(scope=$resolve.scope, date=last_week, time=070000-090000, taxi_status=vacant) | G27: DATA_AUGMENTATION_GUIDE 기준 의미·조건 조합 증강 | H27: PASSAGE_COUNT | I27: medium | J27: spatial_ref=대구/동인동; space=admin; date=last_week; time=070000-090000; taxi_status=vacant | K27: admin | M27: aug300-126 | N27: F059 | O27: status_vacant, agg_absent | P27: 056 | Q27: 0.364 | S27: N | T27: aux_test_v1 final_v12/f31 | U27: 0.217 | V27: train | W27: family 단위 분할(train family)
A28: 127 | B28: 127 | C28: 주말 오전 7시부터 9시까지 scope:h3:8830e1d87ffffff에서 개인택시가 얼마나 통행했어? | F28: get_passage_count(scope=scope:h3:8830e1d87ffffff, date=weekend, time=070000-090000, taxi_type=private) | G28: DATA_AUGMENTATION_GUIDE 기준 의미·조건 조합 증강 | H28: PASSAGE_COUNT | I28: medium | J28: spatial_ref=scope:h3:8830e1d87ffffff; space=direct_scope; date=weekend; time=070000-090000; taxi_type=private | K28: direct_scope | M28: aug300-127 | N28: F040 | O28: agg_absent, direct_scope | P28: 051 | Q28: 0.41 | S28: N | T28: selection_v2 indepv3/m28 | U28: 0.239 | V28: train | W28: family 단위 분할(train family)
... A30: 129 | B30: 129 | C30: 이번 주 대구 서구의 법인 공차 택시 통행량을 알려줘. | F30: get_place_scope(name=서구, region=대구) get_passage_count(scope=$resolve.scope, date=this_week, taxi_type=corporate, taxi_status=vacant) | G30: DATA_AUGMENTATION_GUIDE 기준 의미·조건 조합 증강 | H30: PASSAGE_COUNT | I30: medium | J30: spatial_ref=대구/서구; space=admin; date=this_week; taxi_type=corporate; taxi_status=vacant | K30: admin | M30: aug300-129 | N30: F058 | O30: status_vacant, agg_absent | P30: 019 | Q30: 0.2 | S30: Y | T30: valid98 heldout_v9/h26 | U30: 0.257 | V30: train | W30: family 단위 분할(train family)
A31: 130 | B31: 130 | C31: 이번 달 부산 부산진구의 읍면동별 법인택시 통행량을 알려줘. | F31: get_place_scope(name=부산진구, region=부산) get_passage_count(scope=$resolve.scope, date=this_month, taxi_type=corporate, dimension=emd) | G31: DATA_AUGMENTATION_GUIDE 기준 의미·조건 조합 증강 | H31: PASSAGE_COUNT | I31: medium | J31: spatial_ref=부산/부산진구; space=admin; date=this_month; taxi_type=corporate; group_by=emd | K31: admin | L31: Factors / 정답 Tool / 질문 수정(셀 메모 참고) | M31: aug300-130 | N31: F056 | O31: agg_absent, group_by | P31: 079 | Q31: 0.25 | S31: N | T31: selection_v2 old44/g06 | U31: 0.306 | V31: train | W31: family 단위 분할(train family)
A32: 131 | B32: 131 | C32: 지난주 오후 6시부터 8시까지 대구의 읍면동별 법인 공차 택시 통행량 상위 3곳은? | F32: get_place_scope(name=대구) get_passage_count(scope=$resolve.scope, date=last_week, time=180000-200000, taxi_type=corporate, taxi_status=vacant, dimension=emd, order=top, limit=3) | G32: DATA_AUGMENTATION_GUIDE 기준 의미·조건 조합 증강 | H32: PASSAGE_COUNT | I32: complex | J32: spatial_ref=대구; space=admin; date=last_week; time=180000-200000; taxi_type=corporate; taxi_status=vacant; group_by=emd; order=top; limit=3 | K32: admin | M32: aug300-131 | N32: F048 | O32: status_vacant, agg_absent, group_by, ranking | P32: 046 | Q32: 0.477 | S32: Y | T32: selection_v2 old44/g06 | U32: 0.244 | V32: train | W32: family 단위 분할(train family)
A33: 132 | B33: 132 | C33: 이번 달 부산에서 시군구별 법인 실차 택시 통행량을 집계했을 때 상위 2곳은? | F33: get_place_scope(name=부산) get_passage_count(scope=$resolve.scope, date=this_month, taxi_type=corporate, taxi_status=occupied, dimension=sigungu, order=top, limit=2) | G33: DATA_AUGMENTATION_GUIDE 기준 의미·조건 조합 증강 | H33: PASSAGE_COUNT | I33: complex | J33: spatial_ref=부산; space=admin; date=this_month; taxi_type=corporate; taxi_status=occupied; group_by=sigungu; order=top; limit=2 | K33: admin | M33: aug300-132 | N33: F049 | O33: occupied_passage, agg_absent, group_by, ranking | P33: 005 | Q33: 0.514 | R33: 005 | S33: Y | T33: selection_v2 contrast/c05a | U33: 0.231 | V33: 보류_vendor100 | W33: 정답 tool call이 vendor100 005와 같음; vendor100 005와 Jaccard 0.514. 결정 D1에 따라 train 복귀 가능(holdout에는 넣지 않음)
A34: 133 | B34: 133 | C34: 주말 오전 7시부터 9시까지 대구 중구의 H3 셀별 개인택시 통행량 상위 2곳은? | F34: get_place_scope(name=중구, region=대구) get_passage_count(scope=$resolve.scope, date=weekend, time=070000-090000, taxi_type=private, dimension=h3, order=top, limit=2) | G34: DATA_AUGMENTATION_GUIDE 기준 의미·조건 조합 증강 | H34: PASSAGE_COUNT | I34: complex | J34: spatial_ref=대구/중구; space=admin; date=weekend; time=070000-090000; taxi_type=private; group_by=h3; order=top; limit=2 | K34: admin | M34: aug300-133 | N34: F054 | O34: agg_absent, group_by, ranking | P34: 032 | Q34: 0.459 | S34: N | T34: selection_v2 old44/g06 | U34: 0.222 | V34: holdout | W34: family 단위 분할(holdout family)
A35: 134 | B35: 134 | C35: 주말 오후 6시부터 8시까지 부산 광안리 주변의 읍면동별 법인 공차 택시 통행량 하위 3곳은? | F35: get_place_scope(name=광안리, region=부산, include_vicinity=true) get_passage_count(scope=$resolve.scope, date=weekend, time=180000-200000, taxi_type=corporate, taxi_status=vacant, dimension=emd, order=bottom, limit=3) | G35: DATA_AUGMENTATION_GUIDE 기준 의미·조건 조합 증강 | H35: PASSAGE_COUNT | I35: complex | J35: spatial_ref=부산/광안리(vicinity); space=vicinity; date=weekend; time=180000-200000; taxi_type=corporate; taxi_status=vacant; group_by=emd; order=bottom; limit=3 | K35: vicinity | M35: aug300-134 | N35: F047 | O35: status_vacant, vicinity, agg_absent, group_by, ranking | P35: 001 | Q35: 0.362 | S35: N | T35: selection_v2 old44/g06 | U35: 0.224 | V35: train | W35: family 단위 분할(train family)
A36: 135 | B36: 135 | C36: 휴일 오후 6시부터 8시까지 부산 초읍동 어린이대공원 주변의 읍면동별 개인 대기영업 택시 통행량 상위 2곳은? | F36: get_place_scope(name=어린이대공원, region=부산 초읍동, include_vicinity=true) get_passage_count(scope=$resolve.scope, date=holiday, time=180000-200000, taxi_type=private, taxi_status=stationary, dimension=emd, order=top, limit=2) | G36: DATA_AUGMENTATION_GUIDE 기준 의미·조건 조합 증강 | H36: PASSAGE_COUNT | I36: complex | J36: spatial_ref=부산 초읍동/어린이대공원(vicinity); space=vicinity; date=holiday; time=180000-200000; taxi_type=private; taxi_status=stationary; group_by=emd; order=top; limit=2 | K36: vicinity | M36: aug300-135 | N36: F047 | O36: status_stationary, vicinity, agg_absent, group_by, ranking | P36: 064 | Q36: 0.4 | S36: N | T36: selection_v2 contrast/c05a | U36: 0.167 | V36: train | W36: family 단위 분할(train family)
A37: 136 | B37: 136 | C37: 지난주 자정부터 오전 4시까지 scope:district:2700000000의 시군구별 공차 택시 통행량 하위 2곳은? | F37: get_passage_count(scope=scope:district:2700000000, date=last_week, time=000000-040000, taxi_status=vacant, dimension=sigungu, order=bottom, limit=2) | G37: DATA_AUGMENTATION_GUIDE 기준 의미·조건 조합 증강 | H37: PASSAGE_COUNT | I37: complex | J37: spatial_ref=scope:district:2700000000; space=direct_scope; date=last_week; time=000000-040000; taxi_status=vacant; group_by=sigungu; order=bottom; limit=2 | K37: direct_scope | M37: aug300-136 | N37: F037 | O37: status_vacant, agg_absent, group_by, ranking, direct_scope | P37: 009 | Q37: 0.462 | S37: N | T37: aux_test_v1 final_v12/f17 | U37: 0.262 | V37: train | W37: family 단위 분할(train family)
A38: 137 | B38: 137 | C38: 지난달 오후 6시부터 8시까지 대구 수성구의 읍면동별 법인 실차 택시 통행량 중 가장 많은 곳은? | F38: get_place_scope(name=수성구, region=대구) get_passage_count(scope=$resolve.scope, date=last_month, time=180000-200000, taxi_type=corporate, taxi_status=occupied, dimension=emd, order=top, limit=1) | G38: DATA_AUGMENTATION_GUIDE 기준 의미·조건 조합 증강 | H38: PASSAGE_COUNT | I38: complex | J38: spatial_ref=대구/수성구; space=admin; date=last_month; time=180000-200000; taxi_type=corporate; taxi_status=occupied; group_by=emd; order=top; limit=1 | K38: admin | M38: aug300-137 | N38: F052 | O38: occupied_passage, agg_absent, group_by, ranking | P38: 037 | Q38: 0.524 | S38: N | T38: selection_v2 old44/g04 | U38: 0.2 | V38: 보류_vendor100 | W38: vendor100 037와 Jaccard 0.524. 결정 D1에 따라 train 복귀 가능(holdout에는 넣지 않음)
A39: 138 | B39: 138 | C39: 주중 오전 8시 30분부터 10시까지 대구 달서구의 읍면동별 개인 공차 택시 통행량 하위 3곳은? | F39: get_place_scope(name=달서구, region=대구) get_passage_count(scope=$resolve.scope, date=weekday, time=083000-100000, taxi_type=private, taxi_status=vacant, dimension=emd, order=bottom, limit=3) | G39: DATA_AUGMENTATION_GUIDE 기준 의미·조건 조합 증강 | H39: PASSAGE_COUNT | I39: complex | J39: spatial_ref=대구/달서구; space=admin; date=weekday; time=083000-100000; taxi_type=private; taxi_status=vacant; group_by=emd; order=bottom; limit=3 | K39: admin | M39: aug300-138 | N39: F052 | O39: status_vacant, agg_absent, group_by, ranking | P39: 008 | Q39: 0.333 | S39: N | T39: selection_v2 old44/g39 | U39: 0.208 | V39: holdout | W39: family 단위 분할(holdout family)
A40: 139 | B40: 139 | C40: 2026년 6월 2일 오전 7시부터 9시까지 부산 부산진구의 읍면동별 법인 실차 택시 통행량 상위 3곳은? | F40: get_place_scope(name=부산진구, region=부산) get_passage_count(scope=$resolve.scope, date=20260602, time=070000-090000, taxi_type=corporate, taxi_status=occupied, dimension=emd, order=top, limit=3) | G40: DATA_AUGMENTATION_GUIDE 기준 의미·조건 조합 증강 | H40: PASSAGE_COUNT | I40: complex | J40: spatial_ref=부산/부산진구; space=admin; date=20260602; time=070000-090000; taxi_type=corporate; taxi_status=occupied; group_by=emd; order=top; limit=3 | K40: admin | M40: aug300-139 | N40: F052 | O40: occupied_passage, agg_absent, group_by, ranking | P40: 030 | Q40: 0.31 | S40: N | T40: selection_v2 old44/g06 | U40: 0.179 | V40: holdout | W40: family 단위 분할(holdout family)
A41: 140 | B41: 140 | C41: 2026년 6월 1일부터 5일까지 오후 6시부터 8시까지 scope:district:2600000000의 시군구별 실차 택시 통행량 하위 2곳은? | F41: get_passage_count(scope=scope:district:2600000000, date=20260601-20260605, time=180000-200000, taxi_status=occupied, dimension=sigungu, order=bottom, limit=2) | G41: DATA_AUGMENTATION_GUIDE 기준 의미·조건 조합 증강 | H41: PASSAGE_COUNT | I41: complex | J41: spatial_ref=scope:district:2600000000; space=direct_scope; date=20260601-20260605; time=180000-200000; taxi_status=occupied; group_by=sigungu; order=bottom; limit=2 | K41: direct_scope | M41: aug300-140 | N41: F037 | O41: occupied_passage, agg_absent, group_by, ranking, direct_scope | P41: 088 | Q41: 0.343 | S41: N | T41: aux_test_v1 final_v12/f17 | U41: 0.236 | V41: train | W41: family 단위 분할(train family)
A42: 141 | B42: 141 | C42: 2026년 6월 5일 자정부터 오전 4시까지 대구 동구의 읍면동별 개인 대기영업 택시 통행량 상위 2곳은? | F42: get_place_scope(name=동구, region=대구) get_passage_count(scope=$resolve.scope, date=20260605, time=000000-040000, taxi_type=private, taxi_status=stationary, dimension=emd, order=top, limit=2) | G42: DATA_AUGMENTATION_GUIDE 기준 의미·조건 조합 증강 | H42: PASSAGE_COUNT | I42: complex | J42: spatial_ref=대구/동구; space=admin; date=20260605; time=000000-040000; taxi_type=private; taxi_status=stationary; group_by=emd; order=top; limit=2 | K42: admin | M42: aug300-141 | N42: F052 | O42: status_stationary, agg_absent, group_by, ranking | P42: 075 | Q42: 0.277 | S42: N | T42: selection_v2 old44/g06 | U42: 0.179 | V42: holdout | W42: family 단위 분할(holdout family)
...

Sheet 분포_요약
A1: 데이터셋 요약 | B1: 문항 수
A2: 기존 문항 | B2: 100
A3: 추가 증강 문항 | B3: =COUNTA(증강_300!$B:$B)-1 -> 300
A4: 전체 문항 | B4: =B2+B3 -> 400
A6: Semantic Type | B6: 단순 | C6: 중간 | D6: 복합 | E6: 합계
A7: PASSAGE_COUNT | B7: =COUNTIFS(증강_300!$H:$H,$A7,증강_300!$I:$I,"simple") -> 13 | C7: =COUNTIFS(증강_300!$H:$H,$A7,증강_300!$I:$I,"medium") -> 17 | D7: =COUNTIFS(증강_300!$H:$H,$A7,증강_300!$I:$I,"complex") -> 13 | E7: =SUM(B7:D7) -> 43
A8: TRIP_COUNT | B8: =COUNTIFS(증강_300!$H:$H,$A8,증강_300!$I:$I,"simple") -> 13 | C8: =COUNTIFS(증강_300!$H:$H,$A8,증강_300!$I:$I,"medium") -> 17 | D8: =COUNTIFS(증강_300!$H:$H,$A8,증강_300!$I:$I,"complex") -> 13 | E8: =SUM(B8:D8) -> 43
A9: PASSAGE_METRIC | B9: =COUNTIFS(증강_300!$H:$H,$A9,증강_300!$I:$I,"simple") -> 13 | C9: =COUNTIFS(증강_300!$H:$H,$A9,증강_300!$I:$I,"medium") -> 17 | D9: =COUNTIFS(증강_300!$H:$H,$A9,증강_300!$I:$I,"complex") -> 13 | E9: =SUM(B9:D9) -> 43
A10: DRIVE_RATIO | B10: =COUNTIFS(증강_300!$H:$H,$A10,증강_300!$I:$I,"simple") -> 13 | C10: =COUNTIFS(증강_300!$H:$H,$A10,증강_300!$I:$I,"medium") -> 17 | D10: =COUNTIFS(증강_300!$H:$H,$A10,증강_300!$I:$I,"complex") -> 13 | E10: =SUM(B10:D10) -> 43
A11: TRIP_FARE | B11: =COUNTIFS(증강_300!$H:$H,$A11,증강_300!$I:$I,"simple") -> 13 | C11: =COUNTIFS(증강_300!$H:$H,$A11,증강_300!$I:$I,"medium") -> 17 | D11: =COUNTIFS(증강_300!$H:$H,$A11,증강_300!$I:$I,"complex") -> 13 | E11: =SUM(B11:D11) -> 43
A12: OPERATION | B12: =COUNTIFS(증강_300!$H:$H,$A12,증강_300!$I:$I,"simple") -> 13 | C12: =COUNTIFS(증강_300!$H:$H,$A12,증강_300!$I:$I,"medium") -> 17 | D12: =COUNTIFS(증강_300!$H:$H,$A12,증강_300!$I:$I,"complex") -> 13 | E12: =SUM(B12:D12) -> 43
A13: SCOPE_NAME | B13: =COUNTIFS(증강_300!$H:$H,$A13,증강_300!$I:$I,"simple") -> 42 | C13: =COUNTIFS(증강_300!$H:$H,$A13,증강_300!$I:$I,"medium") -> 0 | D13: =COUNTIFS(증강_300!$H:$H,$A13,증강_300!$I:$I,"complex") -> 0 | E13: =SUM(B13:D13) -> 42
A14: 합계 | B14: =SUM(B7:B13) -> 120 | C14: =SUM(C7:C13) -> 102 | D14: =SUM(D7:D13) -> 78 | E14: =SUM(E7:E13) -> 300
A15: ※ 표의 값은 증강_300 시트를 세는 수식(v2). SCOPE_NAME 난이도를 simple로 바로잡아 단순/중간/복합이 90/120/90에서 바뀜.
A16: 실행 방식 | B16: 문항 수
A17: admin | B17: =COUNTIF(증강_300!$K:$K,$A17) -> 154
A18: direct_scope | B18: =COUNTIF(증강_300!$K:$K,$A18) -> 95
A19: global | B19: =COUNTIF(증강_300!$K:$K,$A19) -> 25
A20: vicinity | B20: =COUNTIF(증강_300!$K:$K,$A20) -> 18
A21: place | B21: =COUNTIF(증강_300!$K:$K,$A21) -> 8
A24: 사용 상태(제안, v2) | B24: 문항 수
A25: train | B25: =COUNTIF(증강_300!$V:$V,$A25) -> 162
A26: holdout | B26: =COUNTIF(증강_300!$V:$V,$A26) -> 53
A27: 보류_vendor100 | B27: =COUNTIF(증강_300!$V:$V,$A27) -> 58
A28: 제외 | B28: =COUNTIF(증강_300!$V:$V,$A28) -> 5
A29: 축소 | B29: =COUNTIF(증강_300!$V:$V,$A29) -> 22
A30: 합계 | B30: =SUM(B25:B29) -> 300
A32: Semantic Type × 상태 | B32: train | C32: holdout | D32: 보류_vendor100 | E32: 제외 | F32: 축소 | G32: 합계
A33: PASSAGE_COUNT | B33: =COUNTIFS(증강_300!$H:$H,$A33,증강_300!$V:$V,B$32) -> 27 | C33: =COUNTIFS(증강_300!$H:$H,$A33,증강_300!$V:$V,C$32) -> 8 | D33: =COUNTIFS(증강_300!$H:$H,$A33,증강_300!$V:$V,D$32) -> 8 | E33: =COUNTIFS(증강_300!$H:$H,$A33,증강_300!$V:$V,E$32) -> 0 | F33: =COUNTIFS(증강_300!$H:$H,$A33,증강_300!$V:$V,F$32) -> 0 | G33: =SUM(B33:F33) -> 43
A34: TRIP_COUNT | B34: =COUNTIFS(증강_300!$H:$H,$A34,증강_300!$V:$V,B$32) -> 21 | C34: =COUNTIFS(증강_300!$H:$H,$A34,증강_300!$V:$V,C$32) -> 7 | D34: =COUNTIFS(증강_300!$H:$H,$A34,증강_300!$V:$V,D$32) -> 14 | E34: =COUNTIFS(증강_300!$H:$H,$A34,증강_300!$V:$V,E$32) -> 1 | F34: =COUNTIFS(증강_300!$H:$H,$A34,증강_300!$V:$V,F$32) -> 0 | G34: =SUM(B34:F34) -> 43
A35: PASSAGE_METRIC | B35: =COUNTIFS(증강_300!$H:$H,$A35,증강_300!$V:$V,B$32) -> 25 | C35: =COUNTIFS(증강_300!$H:$H,$A35,증강_300!$V:$V,C$32) -> 9 | D35: =COUNTIFS(증강_300!$H:$H,$A35,증강_300!$V:$V,D$32) -> 9 | E35: =COUNTIFS(증강_300!$H:$H,$A35,증강_300!$V:$V,E$32) -> 0 | F35: =COUNTIFS(증강_300!$H:$H,$A35,증강_300!$V:$V,F$32) -> 0 | G35: =SUM(B35:F35) -> 43
A36: DRIVE_RATIO | B36: =COUNTIFS(증강_300!$H:$H,$A36,증강_300!$V:$V,B$32) -> 27 | C36: =COUNTIFS(증강_300!$H:$H,$A36,증강_300!$V:$V,C$32) -> 8 | D36: =COUNTIFS(증강_300!$H:$H,$A36,증강_300!$V:$V,D$32) -> 7 | E36: =COUNTIFS(증강_300!$H:$H,$A36,증강_300!$V:$V,E$32) -> 1 | F36: =COUNTIFS(증강_300!$H:$H,$A36,증강_300!$V:$V,F$32) -> 0 | G36: =SUM(B36:F36) -> 43
A37: TRIP_FARE | B37: =COUNTIFS(증강_300!$H:$H,$A37,증강_300!$V:$V,B$32) -> 27 | C37: =COUNTIFS(증강_300!$H:$H,$A37,증강_300!$V:$V,C$32) -> 8 | D37: =COUNTIFS(증강_300!$H:$H,$A37,증강_300!$V:$V,D$32) -> 7 | E37: =COUNTIFS(증강_300!$H:$H,$A37,증강_300!$V:$V,E$32) -> 1 | F37: =COUNTIFS(증강_300!$H:$H,$A37,증강_300!$V:$V,F$32) -> 0 | G37: =SUM(B37:F37) -> 43
A38: OPERATION | B38: =COUNTIFS(증강_300!$H:$H,$A38,증강_300!$V:$V,B$32) -> 26 | C38: =COUNTIFS(증강_300!$H:$H,$A38,증강_300!$V:$V,C$32) -> 9 | D38: =COUNTIFS(증강_300!$H:$H,$A38,증강_300!$V:$V,D$32) -> 7 | E38: =COUNTIFS(증강_300!$H:$H,$A38,증강_300!$V:$V,E$32) -> 1 | F38: =COUNTIFS(증강_300!$H:$H,$A38,증강_300!$V:$V,F$32) -> 0 | G38: =SUM(B38:F38) -> 43
A39: SCOPE_NAME | B39: =COUNTIFS(증강_300!$H:$H,$A39,증강_300!$V:$V,B$32) -> 9 | C39: =COUNTIFS(증강_300!$H:$H,$A39,증강_300!$V:$V,C$32) -> 4 | D39: =COUNTIFS(증강_300!$H:$H,$A39,증강_300!$V:$V,D$32) -> 6 | E39: =COUNTIFS(증강_300!$H:$H,$A39,증강_300!$V:$V,E$32) -> 1 | F39: =COUNTIFS(증강_300!$H:$H,$A39,증강_300!$V:$V,F$32) -> 22 | G39: =SUM(B39:F39) -> 42
A40: 합계 | B40: =SUM(B33:B39) -> 162 | C40: =SUM(C33:C39) -> 53 | D40: =SUM(D33:D39) -> 58 | E40: =SUM(E33:E39) -> 5 | F40: =SUM(F33:F39) -> 22 | G40: =SUM(G33:G39) -> 300
A42: 난이도 × 상태 | B42: train | C42: holdout | D42: 보류_vendor100 | E42: 제외 | F42: 축소
A43: simple | B43: =COUNTIFS(증강_300!$I:$I,$A43,증강_300!$V:$V,B$42) -> 52 | C43: =COUNTIFS(증강_300!$I:$I,$A43,증강_300!$V:$V,C$42) -> 18 | D43: =COUNTIFS(증강_300!$I:$I,$A43,증강_300!$V:$V,D$42) -> 24 | E43: =COUNTIFS(증강_300!$I:$I,$A43,증강_300!$V:$V,E$42) -> 4 | F43: =COUNTIFS(증강_300!$I:$I,$A43,증강_300!$V:$V,F$42) -> 22
A44: medium | B44: =COUNTIFS(증강_300!$I:$I,$A44,증강_300!$V:$V,B$42) -> 58 | C44: =COUNTIFS(증강_300!$I:$I,$A44,증강_300!$V:$V,C$42) -> 19 | D44: =COUNTIFS(증강_300!$I:$I,$A44,증강_300!$V:$V,D$42) -> 24 | E44: =COUNTIFS(증강_300!$I:$I,$A44,증강_300!$V:$V,E$42) -> 1 | F44: =COUNTIFS(증강_300!$I:$I,$A44,증강_300!$V:$V,F$42) -> 0
A45: complex | B45: =COUNTIFS(증강_300!$I:$I,$A45,증강_300!$V:$V,B$42) -> 52 | C45: =COUNTIFS(증강_300!$I:$I,$A45,증강_300!$V:$V,C$42) -> 16 | D45: =COUNTIFS(증강_300!$I:$I,$A45,증강_300!$V:$V,D$42) -> 10 | E45: =COUNTIFS(증강_300!$I:$I,$A45,증강_300!$V:$V,E$42) -> 0 | F45: =COUNTIFS(증강_300!$I:$I,$A45,증강_300!$V:$V,F$42) -> 0
...

Sheet 메타
A1: 항목 | B1: 내용
A2: 증강 기준 | B2: 7개 의미 유형 + 실행 조건(Factor) + 표현 다양화
A3: 난이도 비율 | B3: 단순 30% / 중간 40% / 복합 30% (90/120/90) — v2에서 SCOPE_NAME 30건을 simple로 바로잡아 120/102/78
A4: GitHub branch | B4: https://github.com/7829hw/assistant_univ/tree/geoflow/partial-grounding
A5: Query loader | B5: https://github.com/7829hw/assistant_univ/blob/geoflow/partial-grounding/query_loader.py
A6: Tool schema | B6: https://github.com/7829hw/assistant_univ/blob/geoflow/partial-grounding/schemas/tims.yaml
A7: Gazetteer schema | B7: https://github.com/7829hw/assistant_univ/blob/geoflow/partial-grounding/schemas/gazetteer.yaml
A8: Guide source | B8: DATA_AUGMENTATION_GUIDE(3).md
A9: YAML 출력 | B9: id/question 최소 계약에 맞춰 별도 파일 2종 생성
A10: v2 개정일 | B10: 2026-10-15
A11: v2 수정 | B11: 질문 3건(130·305·306) 정답·질문 불일치 수정, SCOPE_NAME 난이도 30건 수정. 수정 셀은 노란색, 셀 메모에 수정 전 값
A12: v2 추가 열 | B12: L–W열: 수정 이력, canonical_id(aug300-<ID>), family_id, risk_tags, 보호셋 겹침 지표, 사용 상태(제안), 상태 사유
... A17: 검증 | B17: 정답 규칙 검사(날짜·시간·택시 유형·상태·순위·limit·집계·묶음 단위·장소명·vicinity) 300건 통과(v2 기준)

Sheet 보호셋_겹침
A1: 질문 ID | B1: 상태 | C1: 질문 | D1: vendor100 ID | E1: vendor100 질문 | F1: Jaccard | G1: 동일 정답 | H1: 기타 보호셋 | I1: 기타 질문 | J1: 기타 Jaccard
A2: 200 | B2: 보류_vendor100 | C2: 지난주 대구 소속 개인택시의 평균 공차율은? | D2: 045 | E2: 지난 주 대구 소속 개인택시의 평균 공차율은? | F2: 1 | G2: 045 | H2: selection_v2 old44/g21 | I2: 주말 대구 소속 택시의 평균 공차율은? | J2: 0.476
A3: 291 | B3: 보류_vendor100 | C3: 지난주 대구에서 승차 건수가 적은 읍면동 하위 2곳은? | D3: 044 | E3: 지난 주 대구에서 승차 건수가 적은 읍면동 하위 2곳은? | F3: 1 | G3: 044 | H3: selection_v2 old44/g06 | I3: 지난 주 대구 중구의 읍면동별 법인택시 통행량 하위 2곳은? | J3: 0.222
A4: 230 | B4: 보류_vendor100 | C4: 대구 소속 택시의 평균 요금은? | D4: 086 | E4: 올해 대구 소속 택시의 평균 요금은? | F4: 0.846 | H4: selection_v2 old44/g21 | I4: 주말 대구 소속 택시의 평균 공차율은? | J4: 0.389
A5: 105 | B5: 보류_vendor100 | C5: 대구 신천동의 공차 택시 통행량은? | D5: 019 | E5: 지난 주 대구 신천동의 공차 택시 통행량은? | F5: 0.812 | H5: selection_v2 old44/g37 | I5: 대구 중앙로동의 택시 통행량은? | J5: 0.25
A6: 114 | B6: 보류_vendor100 | C6: 주말 대구 두류동의 개인 대기영업 택시 통행량은? | D6: 055 | E6: 휴일 대구 두류동의 개인 대기영업 택시 통행량은? | F6: 0.81 | H6: selection_v2 old44/g03 | I6: 휴일 대구 달서구의 대기영업 법인택시 통행량은? | J6: 0.226
A7: 289 | B7: 보류_vendor100 | C7: 지난달 오후 6시부터 8시까지 대구 신천동에서 부산 초량동까지의 실차 구간 건수는? | D7: 022 | E7: 지난달 오후 6시부터 8시까지 대구 신천동에서 부산 초량동에 도착한 실차 구간 건수는? | F7: 0.725 | G7: 022 | H7: selection_v2 contrast/c03a | I7: 이번 주 대구 동인동에서 부산 초량동으로 간 실차 구간 건수는? | J7: 0.261
A8: 243 | B8: 보류_vendor100 | C8: 지난주 대구 소속 택시의 평균 요금은? | D8: 086 | E8: 올해 대구 소속 택시의 평균 요금은? | F8: 0.688 | H8: valid98 heldout_v9/h34 | I8: 지난주 대구 소속 택시들의 평균 요금은 얼마인가요? | J8: 0.478
A9: 354 | B9: 보류_vendor100 | C9: 지난달 대구 수성구 소속 개인택시의 주별 평균 운행 일수 중 중간값은? | D9: 098 | E9: 지난달 대구 소속 개인택시의 주별 평균 운행 일수의 중간값은? | F9: 0.645 | H9: selection_v2 old44/g31 | I9: 지난달 대구 소속 택시의 주별 평균 운행 일수 중 가장 큰 값은? | J9: 0.429
A10: 293 | B10: 보류_vendor100 | C10: 지난주 대구에서 부산까지 이동한 읍면동 간 OD 노선 상위 3개는? | D10: 006 | E10: 대구에서 부산으로 이동한 읍면동 간 OD 노선 상위 3개는? | F10: 0.633 | H10: selection_v2 contrast/c04b | I10: 지난달 대구에서 부산으로 이동한 읍면동 간 노선 상위 3개는? | J10: 0.429
A11: 108 | B11: 보류_vendor100 | C11: 이번 달 scope:district:2600000000의 택시 통행량을 알려줘. | D11: 088 | E11: 이번 달 scope:district:2600000000의 법인 실차 택시 통행량은? | F11: 0.625 | H11: valid98 heldout_v9/h36 | I11: scope:district:2726000000 이 어느 지역인지 이름으로 알려줘. | J11: 0.396
A12: 292 | B12: 보류_vendor100 | C12: 이번 달 부산에 도착한 실차의 하차 건수가 적은 읍면동 하위 2곳은? | D12: 041 | E12: 이번 달 부산에서 하차 건수가 적은 읍면동 하위 2곳은? | F12: 0.621 | G12: 041 | H12: selection_v2 old44/g06 | I12: 지난 주 대구 중구의 읍면동별 법인택시 통행량 하위 2곳은? | J12: 0.114
A13: 195 | B13: 보류_vendor100 | C13: 대구 수성구 소속 개인택시의 평균 공차율은? | D13: 045 | E13: 지난 주 대구 소속 개인택시의 평균 공차율은? | F13: 0.619 | H13: selection_v2 old44/g21 | I13: 주말 대구 소속 택시의 평균 공차율은? | J13: 0.409
A14: 123 | B14: 보류_vendor100 | C14: 이번 달 scope:district:2600000000의 읍면동별 실차 택시 통행량을 알려줘. | D14: 088 | E14: 이번 달 scope:district:2600000000의 법인 실차 택시 통행량은? | F14: 0.614 | H14: valid98 heldout_v9/h36 | I14: scope:district:2726000000 이 어느 지역인지 이름으로 알려줘. | J14: 0.352
A15: 303 | B15: 보류_vendor100 | C15: 2026년 6월 2일 자정부터 오전 4시까지 대구에서 부산까지 이동한 읍면동 간 OD 노선 상위 2개는? | D15: 075 | E15: 2026년 6월 4일 자정부터 오전 4시까지 대구에서 부산으로 이동한 읍면동 간 OD 상위 2개는? | F15: 0.608 | H15: selection_v2 contrast/c04b | I15: 지난달 대구에서 부산으로 이동한 읍면동 간 노선 상위 3개는? | J15: 0.222
A16: 178 | B16: 보류_vendor100 | C16: 2026년 6월 2일 오전 8시 30분부터 10시까지 scope:h3:8830e1d87ffffff의 최대 RPM 값은? | D16: 051 | E16: 주말 오전 8시부터 10시까지 scope:h3:8830e1d87ffffff의 최대 RPM은? | F16: 0.596 | H16: selection_v2 indepv3/m28 | I16: scope:h3:8830e1d8dffffff 구역의 지난달 평균 주행 속도는 얼마였지? | J16: 0.222
A17: 234 | B17: 보류_vendor100 | C17: 대구 수성구 소속 택시의 평균 요금은? | D17: 086 | E17: 올해 대구 소속 택시의 평균 요금은? | F17: 0.588 | H17: selection_v2 old44/g17 | I17: 지난달 서울 소속 개인택시의 평균 요금은? | J17: 0.304
A18: 163 | B18: 보류_vendor100 | C18: 휴일 오후 6시부터 8시까지 부산 초읍동 어린이대공원 주변 기준 RPM 중간값이 얼마야? | D18: 064 | E18: 주말 오후 6시부터 8시까지 부산 초읍동 어린이대공원 주변의 RPM 중간값은? | F18: 0.581 | H18: selection_v2 old44/g18 | I18: 2026년 7월 5일 오후 6시부터 9시까지 부산 소속 택시의 요금 중간값은? | J18: 0.155
A19: 225 | B19: 보류_vendor100 | C19: 2026년 6월 5일 자정부터 오전 4시까지 대구 중구 소속 개인택시의 평균 공차율은? | D19: 039 | E19: 2026년 6월 3일 자정부터 오전 4시까지 대구 소속 개인택시의 최소 공차율은? | F19: 0.581 | H19: selection_v2 old44/g21 | I19: 주말 대구 소속 택시의 평균 공차율은? | J19: 0.225
A20: 212 | B20: 보류_vendor100 | C20: 지난주 개인택시의 평균 공차율은? | D20: 045 | E20: 지난 주 대구 소속 개인택시의 평균 공차율은? | F20: 0.579 | H20: selection_v2 old44/g21 | I20: 주말 대구 소속 택시의 평균 공차율은? | J20: 0.421
A21: 260 | B21: 보류_vendor100 | C21: 주말 오후 6시부터 8시까지 대구 소속 택시의 요금 중간값은? | D21: 059 | E21: 주말 오후 6시부터 8시까지 대구 소속 택시의 평균 요금은? | F21: 0.567 | H21: selection_v2 old44/g18 | I21: 2026년 7월 5일 오후 6시부터 9시까지 부산 소속 택시의 요금 중간값은? | J21: 0.375
A22: 316 | B22: 보류_vendor100 | C22: 대구 소속 택시의 평균 수입은? | D22: 057 | E22: 지난달 부산 소속 택시의 평균 수입은? | F22: 0.562 | H22: aux_test_v1 at/t05d | I22: 지난달 대구 소속 택시의 수입은? | J22: 0.438
A23: 282 | B23: 보류_vendor100 | C23: 부산 안에서 읍면동 간 OD 노선 하위 2개는? | D23: 093 | E23: 이번 달 부산 안에서 이용이 적은 읍면동 간 OD 노선 하위 2개는? | F23: 0.556 | H23: selection_v2 contrast/c04b | I23: 지난달 대구에서 부산으로 이동한 읍면동 간 노선 상위 3개는? | J23: 0.079
A24: 204 | B24: 보류_vendor100 | C24: 지난달 대구 수성구 소속 법인택시의 평균 공차율은? | D24: 028 | E24: 부산 소속 법인택시의 평균 공차율은? | F24: 0.545 | H24: selection_v2 old44/g21 | I24: 주말 대구 소속 택시의 평균 공차율은? | J24: 0.36
A25: 144 | B25: 보류_vendor100 | C25: 대구 중구의 평균 속도는? | D25: 033 | E25: 대구 중구의 택시 평균 속도는? | F25: 0.538 | G25: 033 | H25: valid98 heldout_v9/h31 | I25: 지난달 수성구를 지난 택시들의 평균 속도는 얼마였어? | J25: 0.154
A26: 147 | B26: 보류_vendor100 | C26: scope:h3:8830e1d87ffffff의 최대 RPM 값을 조회해줘. | D26: 051 | E26: 주말 오전 8시부터 10시까지 scope:h3:8830e1d87ffffff의 최대 RPM은? | F26: 0.532 | H26: selection_v2 indepv3/m28 | I26: scope:h3:8830e1d8dffffff 구역의 지난달 평균 주행 속도는 얼마였지? | J26: 0.302
A27: 248 | B27: 보류_vendor100 | C27: 주중 오후 6시부터 8시까지 대구 달서구 소속 택시의 평균 요금을 알려줘. | D27: 059 | E27: 주말 오후 6시부터 8시까지 대구 소속 택시의 평균 요금은? | F27: 0.529 | H27: selection_v2 old44/g21 | I27: 주말 대구 소속 택시의 평균 공차율은? | J27: 0.162
A28: 112 | B28: 보류_vendor100 | C28: scope:district:2700000000의 시군구별 택시 통행량을 알려줘. | D28: 042 | E28: 지난 주 scope:district:2700000000의 공차 택시 통행량은? | F28: 0.524 | H28: valid98 heldout_v9/h36 | I28: scope:district:2726000000 이 어느 지역인지 이름으로 알려줘. | J28: 0.36
A29: 137 | B29: 보류_vendor100 | C29: 지난달 오후 6시부터 8시까지 대구 수성구의 읍면동별 법인 실차 택시 통행량 중 가장 많은 곳은? | D29: 037 | E29: 지난달 대구 수성구의 읍면동별 실차 택시 통행량 중 가장 많은 곳은? | F29: 0.524 | H29: selection_v2 old44/g04 | I29: 주중 대구의 시군구별 실차 택시 통행량이 가장 많은 곳은? | J29: 0.2
A30: 398 | B30: 보류_vendor100 | C30: scope:district:2617010100의 대응 지역명은? | D30: 066 | E30: scope:district:2617010100에 도착한 실차 구간 건수는? | F30: 0.524 | H30: selection_v2 old44/g35 | I30: scope:district:2723010200에서 출발해 scope:district:2617010100에 도착한 실차 구간 건수는? | J30: 0.393
A31: 369 | B31: 보류_vendor100 | C31: scope:district:2723510100의 대응 지역명은? | D31: 097 | E31: scope:district:2723510100에서 출발한 실차 구간 건수는? | F31: 0.523 | H31: selection_v2 indepv4/k21 | I31: 집계표에 scope:district:2723010100 이라고 나와 있는데 이게 어느 동이야? | J31: 0.377
A32: 333 | B32: 보류_vendor100 | C32: 지난주 대구 수성구 소속 개인택시의 평균 운행 일수는? | D32: 063 | E32: 지난 주 개인택시의 평균 운행 일수는? | F32: 0.522 | H32: selection_v2 old44/g26 | I32: 이번 달 대구 소속 택시의 평균 운행 일수는? | J32: 0.37
A33: 203 | B33: 보류_vendor100 | C33: 주말 인천 소속 개인택시의 공차율 중간값을 조회해줘. | D33: 004 | E33: 휴일 인천 소속 개인택시의 공차율 중간값은? | F33: 0.52 | H33: valid98 heldout_v8/r09 | I33: 지난달 부산 소속 택시의 요금 중간값을 조회해 주십시오 | J33: 0.167
A34: 331 | B34: 보류_vendor100 | C34: 이번 달 서울 소속 법인택시 기준 평균 활성택시 대수가 얼마야? | D34: 049 | E34: 이번 달 서울 소속 법인택시의 평균 활성택시 대수는? | F34: 0.517 | G34: 049 | H34: selection_v2 indepv4/k15 | I34: 이번 달 서울 소속 법인택시 하루 수입 평균 좀 알려 줄래? | J34: 0.25
A35: 132 | B35: 보류_vendor100 | C35: 이번 달 부산에서 시군구별 법인 실차 택시 통행량을 집계했을 때 상위 2곳은? | D35: 005 | E35: 이번 달 부산의 시군구별 법인 실차 택시 통행량 상위 2곳은? | F35: 0.514 | G35: 005 | H35: selection_v2 contrast/c05a | I35: 주말 대구의 시군구별 택시 통행량 상위 2곳은? | J35: 0.231
A36: 397 | B36: 보류_vendor100 | C36: scope:h3:8830e1d87ffffff의 대응 지역명은? | D36: 082 | E36: scope:h3:8830e1d87ffffff가 가리키는 지역명을 알려줘. | F36: 0.513 | G36: 082 | H36: selection_v2 indepv3/m28 | I36: scope:h3:8830e1d8dffffff 구역의 지난달 평균 주행 속도는 얼마였지? | J36: 0.333
A37: 366 | B37: 보류_vendor100 | C37: scope:h3:8830e1d87ffffff에 대응하는 장소 이름을 알려줘. | D37: 082 | E37: scope:h3:8830e1d87ffffff가 가리키는 지역명을 알려줘. | F37: 0.512 | G37: 082 | H37: selection_v2 indepv3/m28 | I37: scope:h3:8830e1d8dffffff 구역의 지난달 평균 주행 속도는 얼마였지? | J37: 0.296
A38: 175 | B38: 보류_vendor100 | C38: 주말 오후 6시부터 8시까지 부산 초읍동 어린이대공원 주변에서 기록된 최대 RPM 값을 알려줘. | D38: 064 | E38: 주말 오후 6시부터 8시까지 부산 초읍동 어린이대공원 주변의 RPM 중간값은? | F38: 0.511 | H38: selection_v2 indepv4/k05 | I38: 부산 어린이대공원 구간 도로에서 평일에 잰 택시 속도의 중앙값을 알려 줘. | J38: 0.133
A39: 359 | B39: 보류_vendor100 | C39: scope:h3:8830e1d87ffffff의 사람이 읽을 수 있는 지역·장소명을 알려줘. | D39: 082 | E39: scope:h3:8830e1d87ffffff가 가리키는 지역명을 알려줘. | F39: 0.511 | G39: 082 | H39: selection_v2 indepv3/m28 | I39: scope:h3:8830e1d8dffffff 구역의 지난달 평균 주행 속도는 얼마였지? | J39: 0.267
A40: 276 | B40: 보류_vendor100 | C40: 출발지가 scope:district:2723510100인 실차 구간은 몇 건이야? | D40: 097 | E40: scope:district:2723510100에서 출발한 실차 구간 건수는? | F40: 0.51 | G40: 097 | H40: selection_v2 indepv4/k21 | I40: 집계표에 scope:district:2723010100 이라고 나와 있는데 이게 어느 동이야? | J40: 0.356
...

Sheet 수정_이력
A1: 질문 ID | B1: 열 | C1: 수정 전 | D1: 수정 후 | E1: 사유
A2: 305 | B2: 질문 | C2: 주말 오후 6시부터 8시까지 부산에 도착한 실차의 하차 건수가 많은 읍면동 상위 3곳은? | D2: 주말 오후 6시부터 8시까지 대구 수성구에서 손님을 태워 부산에 도착한 실차의 하차 읍면동 상위 3곳은? | E2: 질문이 정답·Factors(spatial_ref=대구/수성구|부산)의 출발 조건을 빠뜨림. 정답을 유지하고 질문에 출발지를 복원(od_role pickup ≠ dimension_target dropoff 문항이 됨)
A3: 306 | B3: 질문 | C3: 주중 오전 8시 30분부터 10시까지 대구에서 승차 건수가 적은 읍면동 하위 2곳은? | D3: 주중 오전 8시 30분부터 10시까지 부산 수영구로 간 실차를 기준으로, 대구에서 승차가 가장 적은 읍면동 2곳은? | E3: 질문이 정답·Factors(spatial_ref=대구|부산/수영구)의 도착 조건을 빠뜨림. 정답을 유지하고 질문에 도착지를 복원(od_role dropoff ≠ dimension_target pickup 문항이 됨)
A4: 130 | B4: 질문 | C4: 이번 달 부산 초량동의 읍면동별 법인택시 통행량을 알려줘. | D4: 이번 달 부산 부산진구의 읍면동별 법인택시 통행량을 알려줘. | E4: 초량동은 읍면동 단위라 "초량동의 읍면동별"은 한 행짜리 퇴화 질문. 같은 시의 시군구로 교체
A5: 130 | B5: 정답 Tool | C5: get_place_scope(name=초량동, region=부산) get_passage_count(scope=$resolve.scope, date=this_month, taxi_type=corporate, dimension=emd) | D5: get_place_scope(name=부산진구, region=부산) get_passage_count(scope=$resolve.scope, date=this_month, taxi_type=corporate, dimension=emd) | E5: 130 질문 수정에 맞춤
A6: 130 | B6: Factors | C6: spatial_ref=부산/초량동; space=admin; date=this_month; taxi_type=corporate; group_by=emd | D6: spatial_ref=부산/부산진구; space=admin; date=this_month; taxi_type=corporate; group_by=emd | E6: 130 질문 수정에 맞춤
A7: 371 | B7: 난이도 | C7: medium | D7: simple | E7: SCOPE_NAME은 모두 get_scope_name 한 번 호출로 같은 구조. medium·complex 표시는 근거 없음
A8: 372 | B8: 난이도 | C8: medium | D8: simple | E8: SCOPE_NAME은 모두 get_scope_name 한 번 호출로 같은 구조. medium·complex 표시는 근거 없음
A9: 373 | B9: 난이도 | C9: medium | D9: simple | E9: SCOPE_NAME은 모두 get_scope_name 한 번 호출로 같은 구조. medium·complex 표시는 근거 없음
A10: 374 | B10: 난이도 | C10: medium | D10: simple | E10: SCOPE_NAME은 모두 get_scope_name 한 번 호출로 같은 구조. medium·complex 표시는 근거 없음
A11: 375 | B11: 난이도 | C11: medium | D11: simple | E11: SCOPE_NAME은 모두 get_scope_name 한 번 호출로 같은 구조. medium·complex 표시는 근거 없음
A12: 376 | B12: 난이도 | C12: medium | D12: simple | E12: SCOPE_NAME은 모두 get_scope_name 한 번 호출로 같은 구조. medium·complex 표시는 근거 없음
... A38: - | B38: 분포_요약 | C38: 숫자 직접 입력 | D38: 증강_300을 세는 COUNTIFS 수식 | E38: 수정 뒤 값이 자동으로 맞도록

Sheet 보강_필요
A1: 약점 | B1: 300문항 안 현황(v2) | C1: 왜 필요한가 | D1: 채울 곳
A2: "실차" 없는 occupied 통행량 표현(손님·승객을 태운 택시의 통행량) | B2: 0건. occupied 10건 모두 "실차"라는 단어를 그대로 씀 | C2: pilot_004에서 "실차" 표현(g02·g04)은 해결됐고 n33("손님을 태운 택시") 유형만 남음 | D2: batch007 후보 27건(결정 104) 검토·승인
A3: implicit endpoint 동사형 dimension_target("태운 곳", "내려준 곳" 기준 묶음) | B3: 0건. dt 32건의 단서는 "승차 건수 / 하차 건수 / OD 노선"으로 명시적 | C3: partial-grounding p0_sft_004에서 canonical 6문항 0/6, implicit_endpoint_verb 부분집합 개선 없음 | D3: partial-grounding reviewed_reasoning_v002 후보(Gap A 동사형). 같은 6문항 반복 대신 새 문항
A4: 순위 없는 dimension_target(묶음만 하고 order 없음) | B4: 0건. dt 문항 32건 모두 order와 함께 나옴 | C4: "순위 질문이면 dt"라는 지름길을 끊기 위한 대조 | D4: 신규 작성(get_trip_count + dimension + dimension_target, order 없음)
A5: OD 조건과 dimension_target이 다른 문항 | B5: 2건(305·306, v2에서 질문 복원으로 생김) | C5: p0_sft_004 od≠dt 부분집합 n=35에서 base 16, JSON-only 7. 가장 약한 경계 | D5: partial-grounding Gap B 승인분 + 신규 작성
A6: scope 역조회 결합(집계 결과 scope → 이름) | B6: 0건. SCOPE_NAME 42건은 단일 get_scope_name 직접 조회 | C6: p0_sft_004에서 scope 역조회 붕괴(8/9 → 1/9)가 NO_MEASURE 구조 오류의 원인 | D6: partial-grounding batch006 Gap C(b006-44–53, 결정 67로 미승인) 재검토
A7: value 없는 place 대조(지역 묶음어를 measure place로 쓰지 않는 예) | B7: 명시적 대조 0건 | C7: p0_sft_004 MULTIPLE_MEASURES 2 → 17. Partial 구조 회귀의 첫째 원인 | D7: 신규 작성. Partial arm 구조 gate의 진단용으로도 사용
A8: SCOPE_NAME 다양성 | B8: 42건이 표현 3종 × scope 14개의 반복 | C8: 같은 꼴 반복은 학습 비중만 키움 | D8: v2에서 scope당 1문항만 남김(축소 22건). 역조회 결합 문항으로 대체 권장
A9: bucket vs dimension 대조(주별·월별 bucket ↔ 요일별 dimension) | B9: bucket 9건(v2 사용 가능 7), dayofweek dimension 다수 | C9: Partial P0.2/P0.3에서 week/month와 dimension 혼동 증가 | D9: 같은 지표·기간에서 bucket/dimension만 다른 쌍 신규 작성
